(dp1
S'output'
p2
S'<type \'exceptions.RuntimeError\'> Failure to connect, tried 5 times:\nTraceback (most recent call last):\n  File "C:\\Users\\Christoph\\Downloads\\web2py\\gluon\\packages\\dal\\pydal\\base.py", line 457, in __init__\n    self._adapter = adapter(**kwargs)\n  File "C:\\Users\\Christoph\\Downloads\\web2py\\gluon\\packages\\dal\\pydal\\adapters\\__init__.py", line 39, in __call__\n    obj = super(AdapterMeta, cls).__call__(*args, **kwargs)\n  File "C:\\Users\\Christoph\\Downloads\\web2py\\gluon\\packages\\dal\\pydal\\adapters\\base.py", line 369, in __init__\n    super(SQLAdapter, self).__init__(*args, **kwargs)\n  File "C:\\Users\\Christoph\\Downloads\\web2py\\gluon\\packages\\dal\\pydal\\adapters\\base.py", line 53, in __init__\n    self.reconnect()\n  File "C:\\Users\\Christoph\\Downloads\\web2py\\gluon\\packages\\dal\\pydal\\connection.py", line 154, in reconnect\n    self.connection = self.connector()\n  File "C:\\Users\\Christoph\\Downloads\\web2py\\gluon\\packages\\dal\\pydal\\adapters\\mysql.py", line 51, in connector\n    return self.driver.connect(**self.driver_args)\n  File "MySQLdb/__init__.py", line 81, in Connect\n  File "MySQLdb/connections.py", line 193, in __init__\nTypeError: \'password\' is an invalid keyword argument for this function\n'
p3
sS'layer'
p4
S'C:\\Users\\Christoph\\Downloads\\web2py\\applications\\WikiPlurality\\controllers/default.py'
p5
sS'code'
p6
S'<code object <module> at 09741920, file "C:\\Users\\Christoph\\Downloads\\web2py\\applications\\WikiPlurality\\controllers/default.py", line 7>'
p7
sS'snapshot'
p8
(dp9
sS'traceback'
p10
S'Traceback (most recent call last):\n  File "C:\\Users\\Christoph\\Downloads\\web2py\\gluon\\restricted.py", line 219, in restricted\n    exec(ccode, environment)\n  File "C:\\Users\\Christoph\\Downloads\\web2py\\applications\\WikiPlurality\\controllers/default.py", line 93, in <module>\n  File "C:\\Users\\Christoph\\Downloads\\web2py\\gluon\\globals.py", line 421, in <lambda>\n    self._caller = lambda f: f()\n  File "C:\\Users\\Christoph\\Downloads\\web2py\\applications\\WikiPlurality\\controllers/default.py", line 27, in queryresult\n    db_test = DAL(\'mysql://root:root@localhost/test\')\n  File "C:\\Users\\Christoph\\Downloads\\web2py\\gluon\\packages\\dal\\pydal\\base.py", line 171, in __call__\n    obj = super(MetaDAL, cls).__call__(*args, **kwargs)\n  File "C:\\Users\\Christoph\\Downloads\\web2py\\gluon\\packages\\dal\\pydal\\base.py", line 477, in __init__\n    "Failure to connect, tried %d times:\\n%s" % (attempts, tb)\nRuntimeError: Failure to connect, tried 5 times:\nTraceback (most recent call last):\n  File "C:\\Users\\Christoph\\Downloads\\web2py\\gluon\\packages\\dal\\pydal\\base.py", line 457, in __init__\n    self._adapter = adapter(**kwargs)\n  File "C:\\Users\\Christoph\\Downloads\\web2py\\gluon\\packages\\dal\\pydal\\adapters\\__init__.py", line 39, in __call__\n    obj = super(AdapterMeta, cls).__call__(*args, **kwargs)\n  File "C:\\Users\\Christoph\\Downloads\\web2py\\gluon\\packages\\dal\\pydal\\adapters\\base.py", line 369, in __init__\n    super(SQLAdapter, self).__init__(*args, **kwargs)\n  File "C:\\Users\\Christoph\\Downloads\\web2py\\gluon\\packages\\dal\\pydal\\adapters\\base.py", line 53, in __init__\n    self.reconnect()\n  File "C:\\Users\\Christoph\\Downloads\\web2py\\gluon\\packages\\dal\\pydal\\connection.py", line 154, in reconnect\n    self.connection = self.connector()\n  File "C:\\Users\\Christoph\\Downloads\\web2py\\gluon\\packages\\dal\\pydal\\adapters\\mysql.py", line 51, in connector\n    return self.driver.connect(**self.driver_args)\n  File "MySQLdb/__init__.py", line 81, in Connect\n  File "MySQLdb/connections.py", line 193, in __init__\nTypeError: \'password\' is an invalid keyword argument for this function\n\n'
p11
s.